OrderBookSim/OrderBookSim/Outputs/Log1359731137.txt
0--INFO	Added rule
0--INFO	Added rule
0--INFO	Added rule
0--INFO	Added rule
0--INFO	Added trader: Trader[0]: Cash[$1721.24], Holding:GOOG[18113], PositionCash[$1721.24], PositionHolding:GOOG[18113]
0--INFO	Added trader: Trader[1]: Cash[$6253.24], Holding:GOOG[17997], PositionCash[$6253.24], PositionHolding:GOOG[17997]
0--INFO	Added trader: Trader[2]: Cash[$18671.22], Holding:GOOG[4274], PositionCash[$18671.22], PositionHolding:GOOG[4274]
0--INFO	Added trader: Trader[3]: Cash[$15770.74], Holding:GOOG[6478], PositionCash[$15770.74], PositionHolding:GOOG[6478]
0--INFO	Added trader: Trader[4]: Cash[$8036.13], Holding:GOOG[16983], PositionCash[$8036.13], PositionHolding:GOOG[16983]
0--INFO	Added trader: Trader[5]: Cash[$11144.14], Holding:GOOG[19104], PositionCash[$11144.14], PositionHolding:GOOG[19104]
0--INFO	Added trader: Trader[6]: Cash[$3499.86], Holding:GOOG[11262], PositionCash[$3499.86], PositionHolding:GOOG[11262]
0--INFO	Added trader: Trader[7]: Cash[$13061.92], Holding:GOOG[11220], PositionCash[$13061.92], PositionHolding:GOOG[11220]
0--INFO	Added trader: Trader[8]: Cash[$17800.23], Holding:GOOG[15052], PositionCash[$17800.23], PositionHolding:GOOG[15052]
0--INFO	Added trader: Trader[9]: Cash[$10049.13], Holding:GOOG[12288], PositionCash[$10049.13], PositionHolding:GOOG[12288]
0--INFO	Added trader: Trader[10]: Cash[$18040.10], Holding:GOOG[7273], PositionCash[$18040.10], PositionHolding:GOOG[7273]
0--INFO	Added trader: Trader[11]: Cash[$12732.93], Holding:GOOG[15515], PositionCash[$12732.93], PositionHolding:GOOG[15515]
0--INFO	Added trader: Trader[12]: Cash[$15887.94], Holding:GOOG[11827], PositionCash[$15887.94], PositionHolding:GOOG[11827]
0--INFO	Added trader: Trader[13]: Cash[$2865.69], Holding:GOOG[6323], PositionCash[$2865.69], PositionHolding:GOOG[6323]
0--INFO	Added trader: Trader[14]: Cash[$3664.66], Holding:GOOG[9578], PositionCash[$3664.66], PositionHolding:GOOG[9578]
0--INFO	Added trader: Trader[15]: Cash[$5351.73], Holding:GOOG[19954], PositionCash[$5351.73], PositionHolding:GOOG[19954]
0--INFO	Added trader: Trader[16]: Cash[$18905.00], Holding:GOOG[15528], PositionCash[$18905.00], PositionHolding:GOOG[15528]
0--INFO	Added trader: Trader[17]: Cash[$18253.73], Holding:GOOG[18231], PositionCash[$18253.73], PositionHolding:GOOG[18231]
0--INFO	Added trader: Trader[18]: Cash[$17528.00], Holding:GOOG[15776], PositionCash[$17528.00], PositionHolding:GOOG[15776]
0--INFO	Added trader: Trader[19]: Cash[$2240.67], Holding:GOOG[16146], PositionCash[$2240.67], PositionHolding:GOOG[16146]
0--INFO	Added trader: Trader[20]: Cash[$1727.35], Holding:GOOG[970], PositionCash[$1727.35], PositionHolding:GOOG[970]
0--INFO	Added trader: Trader[21]: Cash[$9538.25], Holding:GOOG[13059], PositionCash[$9538.25], PositionHolding:GOOG[13059]
0--INFO	Added trader: Trader[22]: Cash[$5601.37], Holding:GOOG[2153], PositionCash[$5601.37], PositionHolding:GOOG[2153]
0--INFO	Added trader: Trader[23]: Cash[$15774.41], Holding:GOOG[13325], PositionCash[$15774.41], PositionHolding:GOOG[13325]
0--INFO	Added trader: Trader[24]: Cash[$11893.06], Holding:GOOG[3890], PositionCash[$11893.06], PositionHolding:GOOG[3890]
0--INFO	Added trader: Trader[25]: Cash[$18627.89], Holding:GOOG[19648], PositionCash[$18627.89], PositionHolding:GOOG[19648]
0--INFO	Added trader: Trader[26]: Cash[$19512.92], Holding:GOOG[10697], PositionCash[$19512.92], PositionHolding:GOOG[10697]
0--INFO	Added trader: Trader[27]: Cash[$17375.41], Holding:GOOG[11862], PositionCash[$17375.41], PositionHolding:GOOG[11862]
0--INFO	Added trader: Trader[28]: Cash[$6221.50], Holding:GOOG[8586], PositionCash[$6221.50], PositionHolding:GOOG[8586]
0--INFO	Added trader: Trader[29]: Cash[$19807.73], Holding:GOOG[6730], PositionCash[$19807.73], PositionHolding:GOOG[6730]
0--INFO	Added trader: Trader[30]: Cash[$16541.64], Holding:GOOG[6588], PositionCash[$16541.64], PositionHolding:GOOG[6588]
0--INFO	Added trader: Trader[31]: Cash[$10080.87], Holding:GOOG[13064], PositionCash[$10080.87], PositionHolding:GOOG[13064]
0--INFO	Added trader: Trader[32]: Cash[$14033.63], Holding:GOOG[15757], PositionCash[$14033.63], PositionHolding:GOOG[15757]
0--INFO	Added trader: Trader[33]: Cash[$1721.24], Holding:GOOG[18113], PositionCash[$1721.24], PositionHolding:GOOG[18113]
0--INFO	Added trader: Trader[34]: Cash[$1721.24], Holding:GOOG[18113], PositionCash[$1721.24], PositionHolding:GOOG[18113]
0--INFO	Added trader: Trader[35]: Cash[$1721.24], Holding:GOOG[18113], PositionCash[$1721.24], PositionHolding:GOOG[18113]
0--INFO	Added trader: Trader[36]: Cash[$1721.24], Holding:GOOG[18113], PositionCash[$1721.24], PositionHolding:GOOG[18113]
0--INFO	Added trader: Trader[37]: Cash[$1721.24], Holding:GOOG[18113], PositionCash[$1721.24], PositionHolding:GOOG[18113]
0--INFO	Added trader: Trader[38]: Cash[$1721.24], Holding:GOOG[18113], PositionCash[$1721.24], PositionHolding:GOOG[18113]
0--INFO	Added trader: Trader[39]: Cash[$1721.24], Holding:GOOG[18113], PositionCash[$1721.24], PositionHolding:GOOG[18113]
0--INFO	Added trader: Trader[40]: Cash[$1721.24], Holding:GOOG[18113], PositionCash[$1721.24], PositionHolding:GOOG[18113]
0--INFO	Added trader: Trader[41]: Cash[$1721.24], Holding:GOOG[18113], PositionCash[$1721.24], PositionHolding:GOOG[18113]
0--INFO	Added trader: Trader[42]: Cash[$1721.24], Holding:GOOG[18113], PositionCash[$1721.24], PositionHolding:GOOG[18113]
0--INFO	Added trader: Trader[43]: Cash[$1721.24], Holding:GOOG[18113], PositionCash[$1721.24], PositionHolding:GOOG[18113]
0--INFO	Added trader: Trader[44]: Cash[$1721.24], Holding:GOOG[18113], PositionCash[$1721.24], PositionHolding:GOOG[18113]
0--INFO	Added trader: Trader[45]: Cash[$1721.24], Holding:GOOG[18113], PositionCash[$1721.24], PositionHolding:GOOG[18113]
0--INFO	Added trader: Trader[46]: Cash[$1721.24], Holding:GOOG[18113], PositionCash[$1721.24], PositionHolding:GOOG[18113]
0--INFO	Added trader: Trader[47]: Cash[$1721.24], Holding:GOOG[18113], PositionCash[$1721.24], PositionHolding:GOOG[18113]
0--INFO	Added trader: Trader[48]: Cash[$1000000.00], Holding:GOOG[10000000], PositionCash[$1000000.00], PositionHolding:GOOG[10000000]
0--INFO	Added trader: Trader[49]: Cash[$1000000.00], Holding:GOOG[10000000], PositionCash[$1000000.00], PositionHolding:GOOG[10000000]
29--INFO	Enqueued order: Price: 0.91, Volume: 802, Type: BUY, Market Order: 0, Participant: 32, Stock:[ID: 0, Symbol: GOOG], Time: 29, OrderNumber: 0
50--INFO	Enqueued order: Price: 0.00, Volume: 934, Type: SELL, Market Order: 1, Participant: 33, Stock:[ID: 0, Symbol: GOOG], Time: 50, OrderNumber: 1
50--INFO	Enqueued order: Price: 0.00, Volume: 324, Type: SELL, Market Order: 1, Participant: 34, Stock:[ID: 0, Symbol: GOOG], Time: 50, OrderNumber: 2
50--INFO	Enqueued order: Price: 0.00, Volume: 219, Type: SELL, Market Order: 1, Participant: 35, Stock:[ID: 0, Symbol: GOOG], Time: 50, OrderNumber: 3
50--INFO	Enqueued order: Price: 2147483647.00, Volume: 175, Type: BUY, Market Order: 1, Participant: 36, Stock:[ID: 0, Symbol: GOOG], Time: 50, OrderNumber: 4
50--INFO	Enqueued order: Price: 2147483647.00, Volume: 561, Type: BUY, Market Order: 1, Participant: 37, Stock:[ID: 0, Symbol: GOOG], Time: 50, OrderNumber: 5
50--INFO	Enqueued order: Price: 0.00, Volume: 606, Type: SELL, Market Order: 1, Participant: 38, Stock:[ID: 0, Symbol: GOOG], Time: 50, OrderNumber: 6
50--INFO	Enqueued order: Price: 2147483647.00, Volume: 903, Type: BUY, Market Order: 1, Participant: 39, Stock:[ID: 0, Symbol: GOOG], Time: 50, OrderNumber: 7
50--INFO	Enqueued order: Price: 0.00, Volume: 776, Type: SELL, Market Order: 1, Participant: 40, Stock:[ID: 0, Symbol: GOOG], Time: 50, OrderNumber: 8
50--INFO	Enqueued order: Price: 2147483647.00, Volume: 416, Type: BUY, Market Order: 1, Participant: 41, Stock:[ID: 0, Symbol: GOOG], Time: 50, OrderNumber: 9
50--INFO	Enqueued order: Price: 0.00, Volume: 184, Type: SELL, Market Order: 1, Participant: 42, Stock:[ID: 0, Symbol: GOOG], Time: 50, OrderNumber: 10
50--INFO	Enqueued order: Price: 0.00, Volume: 998, Type: SELL, Market Order: 1, Participant: 43, Stock:[ID: 0, Symbol: GOOG], Time: 50, OrderNumber: 11
