OrderBookSim/OrderBookSim/Outputs/Log1359731453.txt
0--INFO	Added rule
0--INFO	Added rule
0--INFO	Added rule
0--INFO	Added rule
0--INFO	Added trader: Trader[0]: Cash[$14778.89], Holding:GOOG[3595], PositionCash[$14778.89], PositionHolding:GOOG[3595]
0--INFO	Added trader: Trader[1]: Cash[$15636.46], Holding:GOOG[15349], PositionCash[$15636.46], PositionHolding:GOOG[15349]
0--INFO	Added trader: Trader[2]: Cash[$14084.29], Holding:GOOG[8883], PositionCash[$14084.29], PositionHolding:GOOG[8883]
0--INFO	Added trader: Trader[3]: Cash[$7243.87], Holding:GOOG[14973], PositionCash[$7243.87], PositionHolding:GOOG[14973]
0--INFO	Added trader: Trader[4]: Cash[$19344.46], Holding:GOOG[17209], PositionCash[$19344.46], PositionHolding:GOOG[17209]
0--INFO	Added trader: Trader[5]: Cash[$3559.68], Holding:GOOG[12798], PositionCash[$3559.68], PositionHolding:GOOG[12798]
0--INFO	Added trader: Trader[6]: Cash[$728.78], Holding:GOOG[12982], PositionCash[$728.78], PositionHolding:GOOG[12982]
0--INFO	Added trader: Trader[7]: Cash[$8988.31], Holding:GOOG[4133], PositionCash[$8988.31], PositionHolding:GOOG[4133]
0--INFO	Added trader: Trader[8]: Cash[$10719.32], Holding:GOOG[4855], PositionCash[$10719.32], PositionHolding:GOOG[4855]
0--INFO	Added trader: Trader[9]: Cash[$17402.87], Holding:GOOG[3978], PositionCash[$17402.87], PositionHolding:GOOG[3978]
0--INFO	Added trader: Trader[10]: Cash[$14706.87], Holding:GOOG[14167], PositionCash[$14706.87], PositionHolding:GOOG[14167]
0--INFO	Added trader: Trader[11]: Cash[$12352.67], Holding:GOOG[75], PositionCash[$12352.67], PositionHolding:GOOG[75]
0--INFO	Added trader: Trader[12]: Cash[$14597.61], Holding:GOOG[14986], PositionCash[$14597.61], PositionHolding:GOOG[14986]
0--INFO	Added trader: Trader[13]: Cash[$2912.08], Holding:GOOG[12150], PositionCash[$2912.08], PositionHolding:GOOG[12150]
0--INFO	Added trader: Trader[14]: Cash[$4309.21], Holding:GOOG[4111], PositionCash[$4309.21], PositionHolding:GOOG[4111]
0--INFO	Added trader: Trader[15]: Cash[$10375.07], Holding:GOOG[6762], PositionCash[$10375.07], PositionHolding:GOOG[6762]
0--INFO	Added trader: Trader[16]: Cash[$12014.53], Holding:GOOG[11441], PositionCash[$12014.53], PositionHolding:GOOG[11441]
0--INFO	Added trader: Trader[17]: Cash[$9603.56], Holding:GOOG[11297], PositionCash[$9603.56], PositionHolding:GOOG[11297]
0--INFO	Added trader: Trader[18]: Cash[$10907.32], Holding:GOOG[413], PositionCash[$10907.32], PositionHolding:GOOG[413]
0--INFO	Added trader: Trader[19]: Cash[$2185.74], Holding:GOOG[10663], PositionCash[$2185.74], PositionHolding:GOOG[10663]
0--INFO	Added trader: Trader[20]: Cash[$613.42], Holding:GOOG[7137], PositionCash[$613.42], PositionHolding:GOOG[7137]
0--INFO	Added trader: Trader[21]: Cash[$9049.96], Holding:GOOG[18758], PositionCash[$9049.96], PositionHolding:GOOG[18758]
0--INFO	Added trader: Trader[22]: Cash[$17659.84], Holding:GOOG[17964], PositionCash[$17659.84], PositionHolding:GOOG[17964]
0--INFO	Added trader: Trader[23]: Cash[$10377.51], Holding:GOOG[16137], PositionCash[$10377.51], PositionHolding:GOOG[16137]
0--INFO	Added trader: Trader[24]: Cash[$8139.29], Holding:GOOG[1098], PositionCash[$8139.29], PositionHolding:GOOG[1098]
0--INFO	Added trader: Trader[25]: Cash[$3053.07], Holding:GOOG[18219], PositionCash[$3053.07], PositionHolding:GOOG[18219]
0--INFO	Added trader: Trader[26]: Cash[$11383.40], Holding:GOOG[829], PositionCash[$11383.40], PositionHolding:GOOG[829]
0--INFO	Added trader: Trader[27]: Cash[$2945.65], Holding:GOOG[7116], PositionCash[$2945.65], PositionHolding:GOOG[7116]
0--INFO	Added trader: Trader[28]: Cash[$2533.04], Holding:GOOG[5662], PositionCash[$2533.04], PositionHolding:GOOG[5662]
0--INFO	Added trader: Trader[29]: Cash[$3574.94], Holding:GOOG[7422], PositionCash[$3574.94], PositionHolding:GOOG[7422]
0--INFO	Added trader: Trader[30]: Cash[$6967.99], Holding:GOOG[6520], PositionCash[$6967.99], PositionHolding:GOOG[6520]
0--INFO	Added trader: Trader[31]: Cash[$6676.84], Holding:GOOG[14444], PositionCash[$6676.84], PositionHolding:GOOG[14444]
0--INFO	Added trader: Trader[32]: Cash[$13005.16], Holding:GOOG[767], PositionCash[$13005.16], PositionHolding:GOOG[767]
0--INFO	Added trader: Trader[33]: Cash[$14778.89], Holding:GOOG[3595], PositionCash[$14778.89], PositionHolding:GOOG[3595]
0--INFO	Added trader: Trader[34]: Cash[$14778.89], Holding:GOOG[3595], PositionCash[$14778.89], PositionHolding:GOOG[3595]
0--INFO	Added trader: Trader[35]: Cash[$14778.89], Holding:GOOG[3595], PositionCash[$14778.89], PositionHolding:GOOG[3595]
0--INFO	Added trader: Trader[36]: Cash[$14778.89], Holding:GOOG[3595], PositionCash[$14778.89], PositionHolding:GOOG[3595]
0--INFO	Added trader: Trader[37]: Cash[$14778.89], Holding:GOOG[3595], PositionCash[$14778.89], PositionHolding:GOOG[3595]
0--INFO	Added trader: Trader[38]: Cash[$14778.89], Holding:GOOG[3595], PositionCash[$14778.89], PositionHolding:GOOG[3595]
0--INFO	Added trader: Trader[39]: Cash[$14778.89], Holding:GOOG[3595], PositionCash[$14778.89], PositionHolding:GOOG[3595]
0--INFO	Added trader: Trader[40]: Cash[$14778.89], Holding:GOOG[3595], PositionCash[$14778.89], PositionHolding:GOOG[3595]
0--INFO	Added trader: Trader[41]: Cash[$14778.89], Holding:GOOG[3595], PositionCash[$14778.89], PositionHolding:GOOG[3595]
0--INFO	Added trader: Trader[42]: Cash[$14778.89], Holding:GOOG[3595], PositionCash[$14778.89], PositionHolding:GOOG[3595]
0--INFO	Added trader: Trader[43]: Cash[$14778.89], Holding:GOOG[3595], PositionCash[$14778.89], PositionHolding:GOOG[3595]
0--INFO	Added trader: Trader[44]: Cash[$14778.89], Holding:GOOG[3595], PositionCash[$14778.89], PositionHolding:GOOG[3595]
0--INFO	Added trader: Trader[45]: Cash[$14778.89], Holding:GOOG[3595], PositionCash[$14778.89], PositionHolding:GOOG[3595]
0--INFO	Added trader: Trader[46]: Cash[$14778.89], Holding:GOOG[3595], PositionCash[$14778.89], PositionHolding:GOOG[3595]
0--INFO	Added trader: Trader[47]: Cash[$14778.89], Holding:GOOG[3595], PositionCash[$14778.89], PositionHolding:GOOG[3595]
0--INFO	Added trader: Trader[48]: Cash[$1000000.00], Holding:GOOG[10000000], PositionCash[$1000000.00], PositionHolding:GOOG[10000000]
0--INFO	Added trader: Trader[49]: Cash[$1000000.00], Holding:GOOG[10000000], PositionCash[$1000000.00], PositionHolding:GOOG[10000000]
50--INFO	Enqueued order: Price: 2147483647.00, Volume: 858, Type: BUY, Market Order: 1, Participant: 32, Stock:[ID: 0, Symbol: GOOG], Time: 50, OrderNumber: 0
51--INFO	Enqueued order: Price: 2147483647.00, Volume: 705, Type: BUY, Market Order: 1, Participant: 33, Stock:[ID: 0, Symbol: GOOG], Time: 51, OrderNumber: 1
51--INFO	Enqueued order: Price: 0.00, Volume: 749, Type: SELL, Market Order: 1, Participant: 34, Stock:[ID: 0, Symbol: GOOG], Time: 51, OrderNumber: 2
51--INFO	Enqueued order: Price: 2147483647.00, Volume: 420, Type: BUY, Market Order: 1, Participant: 35, Stock:[ID: 0, Symbol: GOOG], Time: 51, OrderNumber: 3
51--INFO	Enqueued order: Price: 0.00, Volume: 37, Type: SELL, Market Order: 1, Participant: 36, Stock:[ID: 0, Symbol: GOOG], Time: 51, OrderNumber: 4
51--INFO	Enqueued order: Price: 2147483647.00, Volume: 207, Type: BUY, Market Order: 1, Participant: 37, Stock:[ID: 0, Symbol: GOOG], Time: 51, OrderNumber: 5
51--INFO	Enqueued order: Price: 0.00, Volume: 490, Type: SELL, Market Order: 1, Participant: 38, Stock:[ID: 0, Symbol: GOOG], Time: 51, OrderNumber: 6
51--INFO	Enqueued order: Price: 2147483647.00, Volume: 736, Type: BUY, Market Order: 1, Participant: 39, Stock:[ID: 0, Symbol: GOOG], Time: 51, OrderNumber: 7
51--INFO	Enqueued order: Price: 2147483647.00, Volume: 4, Type: BUY, Market Order: 1, Participant: 40, Stock:[ID: 0, Symbol: GOOG], Time: 51, OrderNumber: 8
51--INFO	Enqueued order: Price: 0.00, Volume: 469, Type: SELL, Market Order: 1, Participant: 41, Stock:[ID: 0, Symbol: GOOG], Time: 51, OrderNumber: 9
51--INFO	Enqueued order: Price: 0.00, Volume: 216, Type: SELL, Market Order: 1, Participant: 42, Stock:[ID: 0, Symbol: GOOG], Time: 51, OrderNumber: 10
51--INFO	Enqueued order: Price: 0.00, Volume: 339, Type: SELL, Market Order: 1, Participant: 43, Stock:[ID: 0, Symbol: GOOG], Time: 51, OrderNumber: 11
